<?xml version="1.0"?>
<!--
  SLAM Tracking Car — Robot Description (URDF/Xacro)

  2-wheel differential drive + front caster
  Sensors: LDS02RR LiDAR (top) + ESP32-CAM (front)

  Dimensions (approximate):
  - Chassis: 200mm x 150mm x 60mm
  - Wheel radius: 33mm, width: 26mm
  - Caster radius: 15mm
-->
<robot xmlns:xacro="http://www.ros.org/wiki/xacro" name="slam_tracking_car">

  <!-- ── Properties ─────────────────────────────────────────── -->
  <xacro:property name="chassis_length" value="0.20"/>
  <xacro:property name="chassis_width" value="0.15"/>
  <xacro:property name="chassis_height" value="0.06"/>
  <xacro:property name="chassis_mass" value="1.0"/>

  <xacro:property name="wheel_radius" value="0.033"/>
  <xacro:property name="wheel_width" value="0.026"/>
  <xacro:property name="wheel_mass" value="0.1"/>
  <xacro:property name="wheel_separation" value="0.17"/>

  <xacro:property name="caster_radius" value="0.015"/>
  <xacro:property name="caster_mass" value="0.05"/>

  <xacro:property name="lidar_height" value="0.04"/>
  <xacro:property name="lidar_radius" value="0.035"/>
  <xacro:property name="lidar_mass" value="0.15"/>

  <xacro:property name="camera_size" value="0.025"/>
  <xacro:property name="camera_mass" value="0.01"/>

  <!-- ── Inertia macros ─────────────────────────────────────── -->
  <xacro:macro name="box_inertia" params="m x y z">
    <inertial>
      <mass value="${m}"/>
      <inertia ixx="${m*(y*y+z*z)/12}" ixy="0" ixz="0"
               iyy="${m*(x*x+z*z)/12}" iyz="0"
               izz="${m*(x*x+y*y)/12}"/>
    </inertial>
  </xacro:macro>

  <xacro:macro name="cylinder_inertia" params="m r h">
    <inertial>
      <mass value="${m}"/>
      <inertia ixx="${m*(3*r*r+h*h)/12}" ixy="0" ixz="0"
               iyy="${m*(3*r*r+h*h)/12}" iyz="0"
               izz="${m*r*r/2}"/>
    </inertial>
  </xacro:macro>

  <xacro:macro name="sphere_inertia" params="m r">
    <inertial>
      <mass value="${m}"/>
      <inertia ixx="${2*m*r*r/5}" ixy="0" ixz="0"
               iyy="${2*m*r*r/5}" iyz="0"
               izz="${2*m*r*r/5}"/>
    </inertial>
  </xacro:macro>

  <!-- ── Base footprint (ground projection) ─────────────────── -->
  <link name="base_footprint"/>

  <joint name="base_joint" type="fixed">
    <parent link="base_footprint"/>
    <child link="base_link"/>
    <origin xyz="0 0 ${wheel_radius}" rpy="0 0 0"/>
  </joint>

  <!-- ── Chassis ────────────────────────────────────────────── -->
  <link name="base_link">
    <visual>
      <geometry>
        <box size="${chassis_length} ${chassis_width} ${chassis_height}"/>
      </geometry>
      <material name="blue">
        <color rgba="0.2 0.4 0.8 1.0"/>
      </material>
    </visual>
    <collision>
      <geometry>
        <box size="${chassis_length} ${chassis_width} ${chassis_height}"/>
      </geometry>
    </collision>
    <xacro:box_inertia m="${chassis_mass}" x="${chassis_length}" y="${chassis_width}" z="${chassis_height}"/>
  </link>

  <!-- ── Wheel macro ────────────────────────────────────────── -->
  <xacro:macro name="wheel" params="prefix y_offset">
    <link name="${prefix}_wheel">
      <visual>
        <geometry>
          <cylinder radius="${wheel_radius}" length="${wheel_width}"/>
        </geometry>
        <material name="dark_gray">
          <color rgba="0.2 0.2 0.2 1.0"/>
        </material>
      </visual>
      <collision>
        <geometry>
          <cylinder radius="${wheel_radius}" length="${wheel_width}"/>
        </geometry>
      </collision>
      <xacro:cylinder_inertia m="${wheel_mass}" r="${wheel_radius}" h="${wheel_width}"/>
    </link>

    <joint name="${prefix}_wheel_joint" type="continuous">
      <parent link="base_link"/>
      <child link="${prefix}_wheel"/>
      <origin xyz="${-chassis_length/4} ${y_offset} 0" rpy="${-pi/2} 0 0"/>
      <axis xyz="0 0 1"/>
      <dynamics damping="0.01" friction="0.1"/>
    </joint>
  </xacro:macro>

  <xacro:wheel prefix="left" y_offset="${wheel_separation/2}"/>
  <xacro:wheel prefix="right" y_offset="${-wheel_separation/2}"/>

  <!-- ── Front caster ───────────────────────────────────────── -->
  <link name="caster_wheel">
    <visual>
      <geometry>
        <sphere radius="${caster_radius}"/>
      </geometry>
      <material name="gray">
        <color rgba="0.5 0.5 0.5 1.0"/>
      </material>
    </visual>
    <collision>
      <geometry>
        <sphere radius="${caster_radius}"/>
      </geometry>
    </collision>
    <xacro:sphere_inertia m="${caster_mass}" r="${caster_radius}"/>
  </link>

  <joint name="caster_joint" type="fixed">
    <parent link="base_link"/>
    <child link="caster_wheel"/>
    <origin xyz="${chassis_length/3} 0 ${-(wheel_radius - caster_radius)}" rpy="0 0 0"/>
  </joint>

  <!-- ── LiDAR (LDS02RR) ───────────────────────────────────── -->
  <link name="laser_link">
    <visual>
      <geometry>
        <cylinder radius="${lidar_radius}" length="${lidar_height}"/>
      </geometry>
      <material name="red">
        <color rgba="0.8 0.1 0.1 1.0"/>
      </material>
    </visual>
    <collision>
      <geometry>
        <cylinder radius="${lidar_radius}" length="${lidar_height}"/>
      </geometry>
    </collision>
    <xacro:cylinder_inertia m="${lidar_mass}" r="${lidar_radius}" h="${lidar_height}"/>
  </link>

  <joint name="lidar_joint" type="fixed">
    <parent link="base_link"/>
    <child link="laser_link"/>
    <origin xyz="0 0 ${chassis_height/2 + lidar_height/2}" rpy="0 0 0"/>
  </joint>

  <!-- ── Camera (ESP32-CAM) ─────────────────────────────────── -->
  <link name="camera_link">
    <visual>
      <geometry>
        <box size="${camera_size} ${camera_size} ${camera_size}"/>
      </geometry>
      <material name="green">
        <color rgba="0.1 0.8 0.1 1.0"/>
      </material>
    </visual>
    <collision>
      <geometry>
        <box size="${camera_size} ${camera_size} ${camera_size}"/>
      </geometry>
    </collision>
    <xacro:box_inertia m="${camera_mass}" x="${camera_size}" y="${camera_size}" z="${camera_size}"/>
  </link>

  <joint name="camera_joint" type="fixed">
    <parent link="base_link"/>
    <child link="camera_link"/>
    <origin xyz="${chassis_length/2} 0 ${chassis_height/4}" rpy="0 0 0"/>
  </joint>

  <!-- Camera optical frame (Z forward, X right, Y down — ROS convention) -->
  <link name="camera_optical_frame"/>
  <joint name="camera_optical_joint" type="fixed">
    <parent link="camera_link"/>
    <child link="camera_optical_frame"/>
    <origin xyz="0 0 0" rpy="${-pi/2} 0 ${-pi/2}"/>
  </joint>

  <!-- ── Gazebo plugins (loaded conditionally) ──────────────── -->
  <xacro:include filename="$(find slam_car_bringup)/urdf/gazebo_plugins.xacro"/>

</robot>
